Workbook

Sheet Reporte Diario
S1: CODIGO:
E2: SISTEMA DE GESTION INTEGRADO
E3: REPORTE DIARIO DE ACTIVIDADES DEL TURNO | S3: REV. 0
S4: FECHA:
C6: Fecha: | K6: Promedio HH.EE Cuadrillas Mineria | M6: =+G47 -> 0.24305556
C7: Turno: | K7: Cumplimiento Actividades | M7: =+H49 -> 1
C8: Jefe de Turno: | J8: Resumen | K8: Total MLB | M8: =+G67 -> 132
C9: Grupo: | J9: de KPI | K9: Total M3 Marina | M9: =+G81 -> 294
K10: Total M3 Shotcrete | M10: =+G91 -> 0
K11: Total Avance en Ciclo Minero | M11: =+H53 -> 0.55733029
K12: Total Dotación Turno | M12: =+SUM(D15:D16,D17:D18,K15:K16,K17:K18,P15:P16,P17:P18) -> 63
B14: DOTACION
B15: Minería | C15: Trabajadores | D15: 10 | H15: Electricistas | J15: Trabajadores | K15: 10 | N15: Mecánicos | O15: Trabajadores | P15: 10
C16: Supervisores | D16: 2 | J16: Supervisores | K16: 2 | O16: Supervisores | P16: 2
B17: OO.CC | C17: Trabajadores | D17: 8 | H17: Servicios | J17: Trabajadores | K17: 8 | N17: Subcontratos | O17: Trabajadores | P17: 8
C18: Supervisores | D18: 1 | J18: Supervisores | K18: 1 | O18: Supervisores | P18: 1
B19: Frente | D19: Frente
B20: NIVEL | C20: POSTURA | D20: ACTIVIDAD | E20: DISCIPLINA | F20: RECURSO (CUADRILLA) | G20: EQUIPO ASIGNADO | H20: HORA INICIO | I20: HORA TERMINO | J20: DURACIÓN ACTIVIDAD | K20: CANTIDAD REALIZADA (Pernos, Malla, Shotcrete, Baldadas, Tiros, etc) | L20: UNIDAD | M20: LARGO PERFORACIÓN (m) (Actividades Jumbos) | N20: % AVANCE DE LA ACTIVIDAD | O20: DETALLE DE LA ACTIVIDAD | P20: PERDIDAS OPERACIONALES (PO) | Q20: HORA INICIO | R20: HORA TERMINO | S20: DURACIÓN INTERFERENCIA | U20: PONDERACIÓN CICLO | V20: MLB | W20: Baldadas | X20: Shotcrete
C21: =+Datos!R2 -> Ciclo Minero 10,0 x 7,2 m Galería Inyección Principal | D21: Gestión de Sitio | E21: Minería | F21: C1 | H21: 0.35416667 | I21: 0.38888889 | J21: =+MOD(I21-H21,1) -> 0.034722222 | N21: 1 | Q21: 0.43055556 | R21: 0.47916667 | S21: =+MOD(R21-Q21,1) -> 0.048611111 | U21: =+IFERROR(VLOOKUP(D21,Datos!$R$3:$T$19,3,FALSE), "0") -> 0 | V21: =IF(OR(D21="Perforación de Fortificación", D21="Perforación de Avance", D21="Perforación Desquinche"), K21*M21, "") | W21: =IF(D21="Extracción de Marina Disparo",K21,"") | X21: =IF(OR(D21="Shotcrete", D21="Pre Shotcrete"), K21, "")
C22: =+C21 -> Ciclo Minero 10,0 x 7,2 m Galería Inyección Principal | D22: Perforación de Fortificación | F22: O1 | G22: Jumbo 2 | H22: 0.38888889 | I22: 0.54166667 | J22: =+MOD(I22-H22,1) -> 0.15277778 | K22: 33 | L22: Pernos | M22: 4 | N22: 1 | S22: =+MOD(R22-Q22,1) -> 0 | U22: =+IFERROR(VLOOKUP(D22,Datos!$R$3:$T$19,3,FALSE), "0") -> 0.086138049 | V22: =IF(OR(D22="Perforación de Fortificación", D22="Perforación de Avance", D22="Perforación Desquinche"), K22*M22, "") -> 132 | W22: =IF(D22="Extracción de Marina Disparo",K22,"") | X22: =IF(OR(D22="Shotcrete", D22="Pre Shotcrete"), K22, "")
C23: =+C22 -> Ciclo Minero 10,0 x 7,2 m Galería Inyección Principal | D23: Lechado de Pernos | F23: C1 | G23: MT2 | H23: 0.5625 | I23: 0.64583333 | J23: =+MOD(I23-H23,1) -> 0.083333333 | K23: 33 | L23: Pernos | M23: 4 | N23: 1 | S23: =+MOD(R23-Q23,1) -> 0 | U23: =+IFERROR(VLOOKUP(D23,Datos!$R$3:$T$19,3,FALSE), "0") -> 0.1779806 | V23: =IF(OR(D23="Perforación de Fortificación", D23="Perforación de Avance", D23="Perforación Desquinche"), K23*M23, "") | W23: =IF(D23="Extracción de Marina Disparo",K23,"") | X23: =IF(OR(D23="Shotcrete", D23="Pre Shotcrete"), K23, "")
C24: =+C23 -> Ciclo Minero 10,0 x 7,2 m Galería Inyección Principal | D24: Instalación de Malla | F24: C1 | G24: MT2 | H24: 0.6875 | I24: 0.8125 | J24: =+MOD(I24-H24,1) -> 0.125 | K24: =30*3 -> 90 | L24: m² | M24: 0 | N24: 1 | S24: =+MOD(R24-Q24,1) -> 0 | U24: =+IFERROR(VLOOKUP(D24,Datos!$R$3:$T$19,3,FALSE), "0") -> 0.068454079 | V24: =IF(OR(D24="Perforación de Fortificación", D24="Perforación de Avance", D24="Perforación Desquinche"), K24*M24, "") | W24: =IF(D24="Extracción de Marina Disparo",K24,"") | X24: =IF(OR(D24="Shotcrete", D24="Pre Shotcrete"), K24, "")
C25: =+C24 -> Ciclo Minero 10,0 x 7,2 m Galería Inyección Principal | D25: Extracción de Marina Disparo | F25: O2 | G25: Scoop 1 | H25: 0.64583333 | I25: 0.6875 | J25: =+MOD(I25-H25,1) -> 0.041666667 | K25: 60 | L25: m³ | M25: 0 | N25: 1 | S25: =+MOD(R25-Q25,1) -> 0 | U25: =+IFERROR(VLOOKUP(D25,Datos!$R$3:$T$19,3,FALSE), "0") -> 0.22475756 | V25: =IF(OR(D25="Perforación de Fortificación", D25="Perforación de Avance", D25="Perforación Desquinche"), K25*M25, "") | W25: =IF(D25="Extracción de Marina Disparo",K25,"") -> 60 | X25: =IF(OR(D25="Shotcrete", D25="Pre Shotcrete"), K25, "")
C26: =+C25 -> Ciclo Minero 10,0 x 7,2 m Galería Inyección Principal | S26: =+MOD(R26-Q26,1) -> 0 | U26: =+IFERROR(VLOOKUP(D26,Datos!$R$3:$T$19,3,FALSE), "0") -> 0 | V26: =IF(OR(D26="Perforación de Fortificación", D26="Perforación de Avance", D26="Perforación Desquinche"), K26*M26, "") | W26: =IF(D26="Extracción de Marina Disparo",K26,"") | X26: =IF(OR(D26="Shotcrete", D26="Pre Shotcrete"), K26, "")
C27: =+C26 -> Ciclo Minero 10,0 x 7,2 m Galería Inyección Principal | S27: =+MOD(R27-Q27,1) -> 0 | U27: =+IFERROR(VLOOKUP(D27,Datos!$R$3:$T$19,3,FALSE), "0") -> 0 | V27: =IF(OR(D27="Perforación de Fortificación", D27="Perforación de Avance", D27="Perforación Desquinche"), K27*M27, "") | W27: =IF(D27="Extracción de Marina Disparo",K27,"") | X27: =IF(OR(D27="Shotcrete", D27="Pre Shotcrete"), K27, "")
B28: NIVEL | C28: POSTURA | D28: ACTIVIDAD | E28: DISCIPLINA | F28: RECURSO (CUADRILLA) | G28: EQUIPO ASIGNADO | H28: HORA INICIO | I28: HORA TERMINO | J28: DURACIÓN ACTIVIDAD | K28: CANTIDAD REALIZADA (Pernos, Malla, Shotcrete, Baldadas, Tiros, etc) | L28: UNIDAD | M28: LARGO PERFORACIÓN (m) (Actividades Jumbos) | N28: % AVANCE DE LA ACTIVIDAD | O28: DETALLE DE LA ACTIVIDAD | P28: INTERFERENCIAS REGISTRADAS | Q28: HORA INICIO | R28: HORA TERMINO | S28: DURACIÓN INTERFERENCIA | V28: MLB | W28: Baldadas | X28: Baldadas
C29: =+Datos!R23 -> Ciclo Minero 5,2 x 5,6 m Galería Acceso Portal de Servicio | Q29: 0.43055556 | R29: 0.47916667 | S29: =+MOD(R29-Q29,1) -> 0.048611111 | U29: =+IFERROR(VLOOKUP(D29,Datos!$R$24:$T$40,3,FALSE), "0") -> 0 | V29: =IF(OR(D29="Perforación de Fortificación", D29="Perforación de Avance", D29="Perforación Desquinche"), K29*M29, "") | W29: =IF(D29="Extracción de Marina Disparo",K29,"") | X29: =IF(OR(D29="Shotcrete", D29="Pre Shotcrete"), K29, "")
C30: =+C29 -> Ciclo Minero 5,2 x 5,6 m Galería Acceso Portal de Servicio | S30: =+MOD(R30-Q30,1) -> 0 | U30: =+IFERROR(VLOOKUP(D30,Datos!$R$24:$T$40,3,FALSE), "0") -> 0 | V30: =IF(OR(D30="Perforación de Fortificación", D30="Perforación de Avance", D30="Perforación Desquinche"), K30*M30, "") | W30: =IF(D30="Extracción de Marina Disparo",K30,"") | X30: =IF(OR(D30="Shotcrete", D30="Pre Shotcrete"), K30, "")
C31: =+C30 -> Ciclo Minero 5,2 x 5,6 m Galería Acceso Portal de Servicio | S31: =+MOD(R31-Q31,1) -> 0 | U31: =+IFERROR(VLOOKUP(D31,Datos!$R$24:$T$40,3,FALSE), "0") -> 0 | V31: =IF(OR(D31="Perforación de Fortificación", D31="Perforación de Avance", D31="Perforación Desquinche"), K31*M31, "") | W31: =IF(D31="Extracción de Marina Disparo",K31,"") | X31: =IF(OR(D31="Shotcrete", D31="Pre Shotcrete"), K31, "")
C32: =+C31 -> Ciclo Minero 5,2 x 5,6 m Galería Acceso Portal de Servicio | S32: =+MOD(R32-Q32,1) -> 0 | U32: =+IFERROR(VLOOKUP(D32,Datos!$R$24:$T$40,3,FALSE), "0") -> 0 | V32: =IF(OR(D32="Perforación de Fortificación", D32="Perforación de Avance", D32="Perforación Desquinche"), K32*M32, "") | W32: =IF(D32="Extracción de Marina Disparo",K32,"") | X32: =IF(OR(D32="Shotcrete", D32="Pre Shotcrete"), K32, "")
C33: =+C32 -> Ciclo Minero 5,2 x 5,6 m Galería Acceso Portal de Servicio | S33: =+MOD(R33-Q33,1) -> 0 | U33: =+IFERROR(VLOOKUP(D33,Datos!$R$24:$T$40,3,FALSE), "0") -> 0 | V33: =IF(OR(D33="Perforación de Fortificación", D33="Perforación de Avance", D33="Perforación Desquinche"), K33*M33, "") | W33: =IF(D33="Extracción de Marina Disparo",K33,"") | X33: =IF(OR(D33="Shotcrete", D33="Pre Shotcrete"), K33, "")
C34: =+C33 -> Ciclo Minero 5,2 x 5,6 m Galería Acceso Portal de Servicio | S34: =+MOD(R34-Q34,1) -> 0 | U34: =+IFERROR(VLOOKUP(D34,Datos!$R$24:$T$40,3,FALSE), "0") -> 0 | V34: =IF(OR(D34="Perforación de Fortificación", D34="Perforación de Avance", D34="Perforación Desquinche"), K34*M34, "") | W34: =IF(D34="Extracción de Marina Disparo",K34,"") | X34: =IF(OR(D34="Shotcrete", D34="Pre Shotcrete"), K34, "")
C35: =+C34 -> Ciclo Minero 5,2 x 5,6 m Galería Acceso Portal de Servicio | S35: =+MOD(R35-Q35,1) -> 0 | U35: =+IFERROR(VLOOKUP(D35,Datos!$R$24:$T$40,3,FALSE), "0") -> 0 | V35: =IF(OR(D35="Perforación de Fortificación", D35="Perforación de Avance", D35="Perforación Desquinche"), K35*M35, "") | W35: =IF(D35="Extracción de Marina Disparo",K35,"") | X35: =IF(OR(D35="Shotcrete", D35="Pre Shotcrete"), K35, "")
B36: NIVEL | C36: POSTURA | D36: ACTIVIDAD | E36: DISCIPLINA | F36: RECURSO (CUADRILLA) | G36: EQUIPO ASIGNADO | H36: HORA INICIO | I36: HORA TERMINO | J36: DURACIÓN ACTIVIDAD | K36: CANTIDAD REALIZADA (Pernos, Malla, Shotcrete, Baldadas, Tiros, etc) | L36: UNIDAD | M36: LARGO PERFORACIÓN (m) (Actividades Jumbos) | N36: % AVANCE DE LA ACTIVIDAD | O36: DETALLE DE LA ACTIVIDAD | P36: INTERFERENCIAS REGISTRADAS | Q36: HORA INICIO | R36: HORA TERMINO | S36: DURACIÓN INTERFERENCIA | V36: MLB | W36: Baldadas | X36: Baldadas
C37: =+Datos!R43 -> Ciclo Minero 9,6 x 7,2 m Galería Inyección Principal Portal | Q37: 0.43055556 | R37: 0.47916667 | S37: =+MOD(R37-Q37,1) -> 0.048611111 | U37: =+IFERROR(VLOOKUP(D37,Datos!$R$44:$T$60,3,FALSE), "0") -> 0 | V37: =IF(OR(D37="Perforación de Fortificación", D37="Perforación de Avance", D37="Perforación Desquinche"), K37*M37, "") | W37: =IF(D37="Extracción de Marina Disparo",K37,"") | X37: =IF(OR(D37="Shotcrete", D37="Pre Shotcrete"), K37, "")
C38: =+C37 -> Ciclo Minero 9,6 x 7,2 m Galería Inyección Principal Portal | S38: =+MOD(R38-Q38,1) -> 0 | U38: =+IFERROR(VLOOKUP(D38,Datos!$R$44:$T$60,3,FALSE), "0") -> 0 | V38: =IF(OR(D38="Perforación de Fortificación", D38="Perforación de Avance", D38="Perforación Desquinche"), K38*M38, "") | W38: =IF(D38="Extracción de Marina Disparo",K38,"") | X38: =IF(OR(D38="Shotcrete", D38="Pre Shotcrete"), K38, "")
C39: =+C38 -> Ciclo Minero 9,6 x 7,2 m Galería Inyección Principal Portal | S39: =+MOD(R39-Q39,1) -> 0 | U39: =+IFERROR(VLOOKUP(D39,Datos!$R$44:$T$60,3,FALSE), "0") -> 0 | V39: =IF(OR(D39="Perforación de Fortificación", D39="Perforación de Avance", D39="Perforación Desquinche"), K39*M39, "") | W39: =IF(D39="Extracción de Marina Disparo",K39,"") | X39: =IF(OR(D39="Shotcrete", D39="Pre Shotcrete"), K39, "")
C40: =+C39 -> Ciclo Minero 9,6 x 7,2 m Galería Inyección Principal Portal | S40: =+MOD(R40-Q40,1) -> 0 | U40: =+IFERROR(VLOOKUP(D40,Datos!$R$44:$T$60,3,FALSE), "0") -> 0 | V40: =IF(OR(D40="Perforación de Fortificación", D40="Perforación de Avance", D40="Perforación Desquinche"), K40*M40, "") | W40: =IF(D40="Extracción de Marina Disparo",K40,"") | X40: =IF(OR(D40="Shotcrete", D40="Pre Shotcrete"), K40, "")
C41: =+C40 -> Ciclo Minero 9,6 x 7,2 m Galería Inyección Principal Portal | S41: =+MOD(R41-Q41,1) -> 0 | U41: =+IFERROR(VLOOKUP(D41,Datos!$R$44:$T$60,3,FALSE), "0") -> 0 | V41: =IF(OR(D41="Perforación de Fortificación", D41="Perforación de Avance", D41="Perforación Desquinche"), K41*M41, "") | W41: =IF(D41="Extracción de Marina Disparo",K41,"") | X41: =IF(OR(D41="Shotcrete", D41="Pre Shotcrete"), K41, "")
C42: =+C41 -> Ciclo Minero 9,6 x 7,2 m Galería Inyección Principal Portal | S42: =+MOD(R42-Q42,1) -> 0 | U42: =+IFERROR(VLOOKUP(D42,Datos!$R$44:$T$60,3,FALSE), "0") -> 0 | V42: =IF(OR(D42="Perforación de Fortificación", D42="Perforación de Avance", D42="Perforación Desquinche"), K42*M42, "") | W42: =IF(D42="Extracción de Marina Disparo",K42,"") | X42: =IF(OR(D42="Shotcrete", D42="Pre Shotcrete"), K42, "")
...

Sheet 01-07 A
S1: CODIGO:
E2: SISTEMA DE GESTION INTEGRADO
E3: REPORTE DIARIO DE ACTIVIDADES DEL TURNO | S3: REV. 0
S4: FECHA:
C6: Fecha: | K6: Promedio HH.EE Cuadrillas Mineria | M6: =+G37 -> #DIV/0!
C7: Turno: | K7: Cumplimiento Actividades | M7: =+H39 -> 0.6254717
C8: Jefe de Turno: | J8: Resumen | K8: Total MLB | M8: =+G57 -> 251
C9: Grupo: | J9: de KPI | K9: Total M3 Marina | M9: =+G71 -> 857.5
K10: Total M3 Shotcrete | M10: =+G81 -> 0
K11: Total Avance en Ciclo Minero | M11: =+#REF! -> #REF!
K12: Total Dotación Turno | M12: =+SUM(D15:D16,D17:D18,K15:K16,K17:K18,P15:P16,P17:P18) -> 63
B14: DOTACION
B15: Minería | C15: Trabajadores | D15: 10 | H15: Electricistas | J15: Trabajadores | K15: 10 | N15: Mecánicos | O15: Trabajadores | P15: 10
C16: Supervisores | D16: 2 | J16: Supervisores | K16: 2 | O16: Supervisores | P16: 2
B17: OO.CC | C17: Trabajadores | D17: 8 | H17: Servicios | J17: Trabajadores | K17: 8 | N17: Subcontratos | O17: Trabajadores | P17: 8
C18: Supervisores | D18: 1 | J18: Supervisores | K18: 1 | O18: Supervisores | P18: 1
B19: Frente | D19: Frente Galeria Auxiliar
B20: NIVEL | C20: POSTURA | D20: ACTIVIDAD | E20: DISCIPLINA | F20: RECURSO (CUADRILLA) | G20: EQUIPO ASIGNADO | H20: HORA INICIO | I20: HORA TERMINO | J20: DURACIÓN ACTIVIDAD | K20: CANTIDAD REALIZADA (Pernos, Malla, Shotcrete, Baldadas, Tiros, etc) | L20: UNIDAD | M20: LARGO PERFORACIÓN (m) (Actividades Jumbos) | N20: % AVANCE DE LA ACTIVIDAD | O20: DETALLE DE LA ACTIVIDAD | P20: PERDIDAS OPERACIONALES (PO) | Q20: HORA INICIO | R20: HORA TERMINO | S20: DURACIÓN INTERFERENCIA | U20: PONDERACIÓN CICLO | V20: MLB | W20: Baldadas | X20: Shotcrete
C21: =+Datos!R2 -> Ciclo Minero 10,0 x 7,2 m Galería Inyección Principal | D21: Gestión de Sitio | E21: Minería | F21: G2-3700 | G21: MT1 | H21: 0.40625 | I21: 0.51041667 | J21: =I21-H21 -> 0.10416667 | K21: 0 | M21: 0 | N21: 0 | S21: =+MOD(R21-Q21,1) -> 0 | U21: =+IFERROR(VLOOKUP(D21,Datos!$R$24:$T$40,3,FALSE), "0") -> 0 | V21: =IF(OR(D21="Perforación de Fortificación", D21="Perforación de Avance", D21="Perforación Desquinche"), K21*M21, "") | W21: =IF(D21="Extracción de Marina Disparo",K21,"") | X21: =IF(OR(D21="Shotcrete", D21="Pre Shotcrete"), K21, "")
C22: =+C21 -> Ciclo Minero 10,0 x 7,2 m Galería Inyección Principal | D22: Extracción de Marina Disparo | F22: O1 | G22: Scoop 1 | H22: 0.52083333 | I22: 0.58333333 | J22: =I22-H22 -> 0.0625 | K22: =50*3.5 -> 175 | L22: m³ | M22: 0 | N22: 0.85 | P22: Scoop F/S | Q22: 0.58333333 | S22: =+MOD(R22-Q22,1) -> 0.41666667 | U22: =+IFERROR(VLOOKUP(D22,Datos!$R$24:$T$40,3,FALSE), "0") -> 0.17399804 | V22: =IF(OR(D22="Perforación de Fortificación", D22="Perforación de Avance", D22="Perforación Desquinche"), K22*M22, "") | W22: =IF(D22="Extracción de Marina Disparo",K22,"") -> 175 | X22: =IF(OR(D22="Shotcrete", D22="Pre Shotcrete"), K22, "")
C23: =+C22 -> Ciclo Minero 10,0 x 7,2 m Galería Inyección Principal | D23: Topografía | H23: 0.625 | I23: 0.67361111 | J23: =I23-H23 -> 0.048611111 | K23: 0 | M23: 0 | N23: 1 | S23: =+MOD(R23-Q23,1) -> 0 | U23: =+IFERROR(VLOOKUP(D23,Datos!$R$24:$T$40,3,FALSE), "0") -> 0.041055718 | V23: =IF(OR(D23="Perforación de Fortificación", D23="Perforación de Avance", D23="Perforación Desquinche"), K23*M23, "") | W23: =IF(D23="Extracción de Marina Disparo",K23,"") | X23: =IF(OR(D23="Shotcrete", D23="Pre Shotcrete"), K23, "")
C24: =+C23 -> Ciclo Minero 10,0 x 7,2 m Galería Inyección Principal | D24: Perforación de Fortificación | F24: O10 | G24: Jumbo 1 | H24: 0.67361111 | I24: 0.76736111 | J24: =I24-H24 -> 0.09375 | K24: 13 | L24: Pernos | M24: 3 | N24: 1 | S24: =+MOD(R24-Q24,1) -> 0 | U24: =+IFERROR(VLOOKUP(D24,Datos!$R$24:$T$40,3,FALSE), "0") -> 0.0742913 | V24: =IF(OR(D24="Perforación de Fortificación", D24="Perforación de Avance", D24="Perforación Desquinche"), K24*M24, "") -> 39 | W24: =IF(D24="Extracción de Marina Disparo",K24,"") | X24: =IF(OR(D24="Shotcrete", D24="Pre Shotcrete"), K24, "")
C25: =+C24 -> Ciclo Minero 10,0 x 7,2 m Galería Inyección Principal | J25: =SUM(J21:J24) -> 0.30902778 | S25: =+MOD(R25-Q25,1) -> 0 | U25: =+IFERROR(VLOOKUP(D25,Datos!$R$24:$T$40,3,FALSE), "0") -> 0 | V25: =IF(OR(D25="Perforación de Fortificación", D25="Perforación de Avance", D25="Perforación Desquinche"), K25*M25, "") | W25: =IF(D25="Extracción de Marina Disparo",K25,"") | X25: =IF(OR(D25="Shotcrete", D25="Pre Shotcrete"), K25, "")
C26: =+C25 -> Ciclo Minero 10,0 x 7,2 m Galería Inyección Principal | S26: =+MOD(R26-Q26,1) -> 0 | U26: =+IFERROR(VLOOKUP(D26,Datos!$R$24:$T$40,3,FALSE), "0") -> 0 | V26: =IF(OR(D26="Perforación de Fortificación", D26="Perforación de Avance", D26="Perforación Desquinche"), K26*M26, "") | W26: =IF(D26="Extracción de Marina Disparo",K26,"") | X26: =IF(OR(D26="Shotcrete", D26="Pre Shotcrete"), K26, "")
D27: Gal. Inyec. Sur nodo 3500
B28: NIVEL | C28: POSTURA | D28: ACTIVIDAD | E28: DISCIPLINA | F28: RECURSO (CUADRILLA) | G28: EQUIPO ASIGNADO | H28: HORA INICIO | I28: HORA TERMINO | J28: DURACIÓN ACTIVIDAD | K28: CANTIDAD REALIZADA (Pernos, Malla, Shotcrete, Baldadas, Tiros, etc) | L28: UNIDAD | M28: LARGO PERFORACIÓN (m) (Actividades Jumbos) | N28: % AVANCE DE LA ACTIVIDAD | O28: DETALLE DE LA ACTIVIDAD | P28: INTERFERENCIAS REGISTRADAS | Q28: HORA INICIO | R28: HORA TERMINO | S28: DURACIÓN INTERFERENCIA | U28: PONDERACIÓN CICLO | V28: MLB | W28: Baldadas | X28: Baldadas
C29: =+Datos!R23 -> Ciclo Minero 5,2 x 5,6 m Galería Acceso Portal de Servicio | D29: Gestión de Sitio | H29: 0.375 | I29: 0.41666667 | J29: =I29-H29 -> 0.041666667 | M29: - | S29: =+MOD(R29-Q29,1) -> 0 | U29: =+IFERROR(VLOOKUP(D29,Datos!$R$3:$T$20,3,FALSE), "0") -> 0 | V29: =IF(OR(D29="Perforación de Fortificación", D29="Perforación de Avance", D29="Perforación Desquinche"), K29*M29, "") | W29: =IF(D29="Extracción de Marina Disparo",K29,"") | X29: =IF(OR(D29="Shotcrete", D29="Pre Shotcrete"), K29, "")
C30: =+C29 -> Ciclo Minero 5,2 x 5,6 m Galería Acceso Portal de Servicio | D30: Perforación de Fortificación | F30: G2-3500 | G30: Jumbo 1 | H30: 0.41666667 | I30: 0.51388889 | J30: =I30-H30 -> 0.097222222 | K30: 53 | L30: Pernos | M30: 4 | N30: 1 | S30: =+MOD(R30-Q30,1) -> 0 | U30: =+IFERROR(VLOOKUP(D30,Datos!$R$3:$T$20,3,FALSE), "0") -> 0.086138049 | V30: =IF(OR(D30="Perforación de Fortificación", D30="Perforación de Avance", D30="Perforación Desquinche"), K30*M30, "") -> 212 | W30: =IF(D30="Extracción de Marina Disparo",K30,"") | X30: =IF(OR(D30="Shotcrete", D30="Pre Shotcrete"), K30, "")
C31: =+C30 -> Ciclo Minero 5,2 x 5,6 m Galería Acceso Portal de Servicio | D31: Lechado de Pernos | F31: G2-3500 | G31: MT1 | H31: 0.51388889 | I31: 0.55555556 | J31: =I31-H31 -> 0.041666667 | K31: 8 | L31: Tiros | M31: 4 | N31: =+K31/$K$30 -> 0.1509434 | S31: =+MOD(R31-Q31,1) -> 0 | U31: =+IFERROR(VLOOKUP(D31,Datos!$R$3:$T$20,3,FALSE), "0") -> 0.1779806 | V31: =IF(OR(D31="Perforación de Fortificación", D31="Perforación de Avance", D31="Perforación Desquinche"), K31*M31, "") | W31: =IF(D31="Extracción de Marina Disparo",K31,"") | X31: =IF(OR(D31="Shotcrete", D31="Pre Shotcrete"), K31, "")
C32: =+C31 -> Ciclo Minero 5,2 x 5,6 m Galería Acceso Portal de Servicio | D32: Lechado de Pernos | F32: G2-3500 | G32: MT1 | H32: 0.63888889 | I32: 0.76388889 | J32: =I32-H32 -> 0.125 | K32: 20 | L32: Tiros | M32: 4 | N32: =+K32/$K$30 -> 0.37735849 | S32: =+MOD(R32-Q32,1) -> 0 | U32: =+IFERROR(VLOOKUP(D32,Datos!$R$3:$T$20,3,FALSE), "0") -> 0.1779806 | V32: =IF(OR(D32="Perforación de Fortificación", D32="Perforación de Avance", D32="Perforación Desquinche"), K32*M32, "") | W32: =IF(D32="Extracción de Marina Disparo",K32,"") | X32: =IF(OR(D32="Shotcrete", D32="Pre Shotcrete"), K32, "")
C33: =+#REF! -> #REF! | J33: =SUM(J29:J32) -> 0.30555556 | S33: =+MOD(R33-Q33,1) -> 0 | U33: =+IFERROR(VLOOKUP(D33,Datos!$R$3:$T$20,3,FALSE), "0") -> 0 | V33: =IF(OR(D33="Perforación de Fortificación", D33="Perforación de Avance", D33="Perforación Desquinche"), K33*M33, "") | W33: =IF(D33="Extracción de Marina Disparo",K33,"") | X33: =IF(OR(D33="Shotcrete", D33="Pre Shotcrete"), K33, "")
C35: KPI de Control Cuadrillas | G35: 3700 | I35: 3500
C36: Cantidad de Cuadrillas Mineras | D36: =SUMPRODUCT((LEFT(F21:F33, 1)="C") / (COUNTIF(F21:F33, F21:F33 & "") + (F21:F33=""))) -> 0 | E36: Meta Horas Efectivas | G36: 0.27083333 | H36: % Cumplimiento | I36: 0.27083333 | J36: % Cumplimiento
C37: Cantidad de Cuadrillas OO.CC | D37: =SUMPRODUCT((LEFT(F21:F33, 1)="O") / (COUNTIF(F21:F33, F21:F33 & "") + (F21:F33=""))) -> 2 | E37: Horas Efectivas Cuadrillas Mineras (Promedio) | G37: =+SUM(SUMIF($F$21:$F$33, "C*", $J$21:$J$33))/SUMPRODUCT((LEFT(F21:F33, 1)="C") / (COUNTIF(F21:F33, F21:F33 & "") + (F21:F33=""))) -> #DIV/0! | H37: =+G37*24/($G$36*24) -> #DIV/0! | I37: =+SUM(SUMIF($F$21:$F$33, "C*", $J$21:$J$33))/SUMPRODUCT((LEFT(H21:H33, 1)="C") / (COUNTIF(H21:H33, H21:H33 & "") + (H21:H33=""))) -> #DIV/0! | J37: =+I37*24/($G$36*24) -> #DIV/0!
E38: Horas Efectivas Cuadrillas OO.CC (Promedio) | G38: =+SUM(SUMIF($F$21:$F$33, "o*", $J$21:$J$33)) -> 0.15625 | H38: =+G38*24/($G$36*24) -> 0.57692308 | I38: =+SUM(SUMIF($F$21:$F$33, "o*", $J$21:$J$33)) -> 0.15625 | J38: =+I38*24/($G$36*24) -> 0.57692308
E39: % Cumplimiento de Actividades | H39: =+AVERAGE(N21:N33) -> 0.6254717 | J39: =+AVERAGE(P21:P33) -> #DIV/0!
I41: Avance Venta | K41: Valor Metro Lineal ($/m) | M41: Av. Disp. | O41: HH unitaria | P41: HH total
E42: % Av. 3700 | H42: =SUMPRODUCT(N21:N27 * U21:U27 * (N21:N27<>"") * (U21:U27<>"")) -> 0.26324536 | I42: =+H42*$K$42*$M$42 -> 5.9419742 | K42: 6.6 | M42: 3.42 | O42: 56.080976 | P42: =+O42*M42*H42 -> 50.489653
E43: % Av. 3500 | H43: =+SUMPRODUCT(N29:N33 * U29:U33 * (N29:N33<>"") * (U29:U33<>"")) -> 0.18016554 | I43: =+H43*$K$43*$M$43 -> 7.2707605 | K43: 11.8 | M43: 3.42 | O43: 118.52056 | P43: =+O43*M43*H43 -> 73.028353
P44: =SUM(P41:P43) -> 123.51801
...

Sheet 01-07 B
S1: CODIGO:
E2: SISTEMA DE GESTION INTEGRADO
E3: REPORTE DIARIO DE ACTIVIDADES DEL TURNO | S3: REV. 0
S4: FECHA:
C6: Fecha: | K6: Promedio HH.EE Cuadrillas Mineria | M6: =+G33 -> #DIV/0!
C7: Turno: | K7: Cumplimiento Actividades | M7: =+H35 -> 1
C8: Jefe de Turno: | J8: Resumen | K8: Total MLB | M8: =+G54 -> 60
C9: Grupo: | J9: de KPI | K9: Total M3 Marina | M9: =+G68 -> 205.8
K10: Total M3 Shotcrete | M10: =+G78 -> 0
K11: Total Avance en Ciclo Minero | M11: =+#REF! -> #REF!
K12: Total Dotación Turno | M12: =+SUM(D15:D16,D17:D18,K15:K16,K17:K18,P15:P16,P17:P18) -> 63
B14: DOTACION
B15: Minería | C15: Trabajadores | D15: 10 | H15: Electricistas | J15: Trabajadores | K15: 10 | N15: Mecánicos | O15: Trabajadores | P15: 10
C16: Supervisores | D16: 2 | J16: Supervisores | K16: 2 | O16: Supervisores | P16: 2
B17: OO.CC | C17: Trabajadores | D17: 8 | H17: Servicios | J17: Trabajadores | K17: 8 | N17: Subcontratos | O17: Trabajadores | P17: 8
C18: Supervisores | D18: 1 | J18: Supervisores | K18: 1 | O18: Supervisores | P18: 1
B19: Frente | D19: Gal. Inyec. Sur nodo 3500
B20: NIVEL | C20: POSTURA | D20: ACTIVIDAD | E20: DISCIPLINA | F20: RECURSO (CUADRILLA) | G20: EQUIPO ASIGNADO | H20: HORA INICIO | I20: HORA TERMINO | J20: DURACIÓN ACTIVIDAD | K20: CANTIDAD REALIZADA (Pernos, Malla, Shotcrete, Baldadas, Tiros, etc) | L20: UNIDAD | M20: LARGO PERFORACIÓN (m) (Actividades Jumbos) | N20: % AVANCE DE LA ACTIVIDAD | O20: DETALLE DE LA ACTIVIDAD | P20: PERDIDAS OPERACIONALES (PO) | Q20: HORA INICIO | R20: HORA TERMINO | S20: DURACIÓN INTERFERENCIA | U20: PONDERACIÓN CICLO | V20: MLB | W20: Baldadas | X20: Shotcrete
C21: =+Datos!R2 -> Ciclo Minero 10,0 x 7,2 m Galería Inyección Principal | D21: Lechado de Pernos | F21: G1-3500 | G21: MT1 | H21: 0.91666667 | I21: 0.03125 | J21: 0.11458333 | K21: 27 | L21: Pernos | M21: 4 | N21: 1 | S21: =+MOD(R21-Q21,1) -> 0 | U21: =+IFERROR(VLOOKUP(D21,Datos!$R$3:$T$19,3,FALSE), "0") -> 0.1779806 | V21: =IF(OR(D21="Perforación de Fortificación", D21="Perforación de Avance", D21="Perforación Desquinche"), K21*M21, "") | W21: =IF(D21="Extracción de Marina Disparo",K21,"") | X21: =IF(OR(D21="Shotcrete", D21="Pre Shotcrete"), K21, "")
C22: =+C21 -> Ciclo Minero 10,0 x 7,2 m Galería Inyección Principal | D22: Instalación de Malla | F22: G1-3500 | G22: MT1 | H22: 0.125 | I22: 0.25 | J22: =I22-H22 -> 0.125 | K22: 150 | L22: m² | M22: 0 | N22: 1 | S22: =+MOD(R22-Q22,1) -> 0 | U22: =+IFERROR(VLOOKUP(D22,Datos!$R$3:$T$19,3,FALSE), "0") -> 0.068454079 | V22: =IF(OR(D22="Perforación de Fortificación", D22="Perforación de Avance", D22="Perforación Desquinche"), K22*M22, "") | W22: =IF(D22="Extracción de Marina Disparo",K22,"") | X22: =IF(OR(D22="Shotcrete", D22="Pre Shotcrete"), K22, "")
C23: =+C22 -> Ciclo Minero 10,0 x 7,2 m Galería Inyección Principal | D23: Extracción de Marina Disparo | F23: G1-3500 | G23: Scoop 1 | K23: 42 | L23: m³ | M23: 0 | N23: 1 | S23: =+MOD(R23-Q23,1) -> 0 | U23: =+IFERROR(VLOOKUP(D23,Datos!$R$3:$T$19,3,FALSE), "0") -> 0.22475756 | V23: =IF(OR(D23="Perforación de Fortificación", D23="Perforación de Avance", D23="Perforación Desquinche"), K23*M23, "") | W23: =IF(D23="Extracción de Marina Disparo",K23,"") -> 42 | X23: =IF(OR(D23="Shotcrete", D23="Pre Shotcrete"), K23, "")
C24: =+C23 -> Ciclo Minero 10,0 x 7,2 m Galería Inyección Principal | J24: =SUM(J21:J23) -> 0.23958333 | X24: =IF(OR(D24="Shotcrete", D24="Pre Shotcrete"), K24, "")
D25: Portal auxilizar nodo 3700
B26: NIVEL | C26: POSTURA | D26: ACTIVIDAD | E26: DISCIPLINA | F26: RECURSO (CUADRILLA) | G26: EQUIPO ASIGNADO | H26: HORA INICIO | I26: HORA TERMINO | J26: DURACIÓN ACTIVIDAD | K26: CANTIDAD REALIZADA (Pernos, Malla, Shotcrete, Baldadas, Tiros, etc) | L26: UNIDAD | M26: LARGO PERFORACIÓN (m) (Actividades Jumbos) | N26: % AVANCE DE LA ACTIVIDAD | O26: DETALLE DE LA ACTIVIDAD | P26: INTERFERENCIAS REGISTRADAS | Q26: HORA INICIO | R26: HORA TERMINO | S26: DURACIÓN INTERFERENCIA | U26: PONDERACIÓN CICLO | V26: MLB | W26: Baldadas | X26: Baldadas
C27: =+#REF! -> #REF! | D27: Perforación de Fortificación | F27: G1-3700 | G27: Jumbo 1 | H27: 0.95833333 | I27: 0.069444444 | J27: 0.11111111 | K27: 20 | L27: Pernos | M27: 3 | N27: 1 | S27: =+MOD(R27-Q27,1) -> 0 | U27: =+IFERROR(VLOOKUP(D27,Datos!$R$24:$T$40,3,FALSE), "0") -> 0.0742913 | V27: =IF(OR(D27="Perforación de Fortificación", D27="Perforación de Avance", D27="Perforación Desquinche"), K27*M27, "") -> 60 | W27: =IF(D27="Extracción de Marina Disparo",K27,"") | X27: =IF(OR(D27="Shotcrete", D27="Pre Shotcrete"), K27, "")
C28: =+C27 -> #REF! | D28: Lechado de Pernos | F28: G1-3700 | G28: MT1 | H28: 0.083333333 | I28: 0.10416667 | J28: =I28-H28 -> 0.020833333 | K28: 0 | M28: 0 | N28: 1 | S28: =+MOD(R28-Q28,1) -> 0 | U28: =+IFERROR(VLOOKUP(D28,Datos!$R$24:$T$40,3,FALSE), "0") -> 0.14662757 | V28: =IF(OR(D28="Perforación de Fortificación", D28="Perforación de Avance", D28="Perforación Desquinche"), K28*M28, "") | W28: =IF(D28="Extracción de Marina Disparo",K28,"") | X28: =IF(OR(D28="Shotcrete", D28="Pre Shotcrete"), K28, "")
C29: =+C28 -> #REF! | D29: Lechado de Pernos | F29: G1-3700 | G29: MT1 | H29: 0.16666667 | I29: 0.26041667 | J29: =I29-H29 -> 0.09375 | K29: 20 | L29: Pernos | M29: 3 | N29: 1 | S29: =+MOD(R29-Q29,1) -> 0 | U29: =+IFERROR(VLOOKUP(D29,Datos!$R$24:$T$40,3,FALSE), "0") -> 0.14662757 | V29: =IF(OR(D29="Perforación de Fortificación", D29="Perforación de Avance", D29="Perforación Desquinche"), K29*M29, "") | W29: =IF(D29="Extracción de Marina Disparo",K29,"") | X29: =IF(OR(D29="Shotcrete", D29="Pre Shotcrete"), K29, "")
J30: =SUM(J27:J29) -> 0.22569444
C31: KPI de Control Cuadrillas
C32: Cantidad de Cuadrillas Mineras | D32: =SUMPRODUCT((LEFT(F21:F29, 1)="C") / (COUNTIF(F21:F29, F21:F29 & "") + (F21:F29=""))) -> 0 | E32: Meta Horas Efectivas | G32: 0.27083333 | H32: % Cumplimiento
C33: Cantidad de Cuadrillas OO.CC | D33: =SUMPRODUCT((LEFT(F21:F29, 1)="O") / (COUNTIF(F21:F29, F21:F29 & "") + (F21:F29=""))) -> 0 | E33: Horas Efectivas Cuadrillas Mineras (Promedio) | G33: =+SUM(SUMIF($F$21:$F$29, "C*", $J$21:$J$29))/SUMPRODUCT((LEFT(F21:F29, 1)="C") / (COUNTIF(F21:F29, F21:F29 & "") + (F21:F29=""))) -> #DIV/0! | H33: =+G33*24/($G$32*24) -> #DIV/0!
E34: Horas Efectivas Cuadrillas OO.CC (Promedio) | G34: =+SUM(SUMIF($F$21:$F$29, "o*", $J$21:$J$29)) -> 0 | H34: =+G34*24/($G$32*24) -> 0
E35: % Cumplimiento de Actividades | H35: =+AVERAGE(N21:N29) -> 1
I38: Avance Venta | K38: Valor Metro Lineal ($/m) | M38: Avance x Disparo (m) | O38: HH unitaria | P38: HH total
E39: % Av. 3700 | H39: =SUMPRODUCT(N21:N24 * U21:U24 * (N21:N24<>"") * (U21:U24<>"")) -> 0.47119224 | I39: =+H39*$K$39*$M$39 -> 10.635751 | K39: 6.6 | M39: 3.42 | O39: 56.080976 | P39: =+O39*M39*H39 -> 90.373229
E40: % Av. 3500 | H40: =+SUMPRODUCT(N27:N29 * U27:U29 * (N27:N29<>"") * (U27:U29<>"")) -> 0.36754643 | I40: =+H40*$K$40*$M$39 -> 14.832704 | K40: 11.8 | M40: 3.42 | O40: 118.52056 | P40: =+O40*M40*H40 -> 148.98138
P41: =SUM(P38:P40) -> 239.35461
C42: KPI de Control Jumbos
C43: Cantidad de Jumbos | D43: =SUMPRODUCT((LEFT(G21:G29, 5)="Jumbo") / (COUNTIF(G21:G29, G21:G29 & "") + (G21:G29=""))) -> 1 | E43: Meta Horas Efectivas | G43: 0.20833333
E44: Meta MLB Turno (Promedio) | G44: =15000/(60) -> 250 | H44: % Cumpl
...

Sheet 02-07A
S1: CODIGO:
E2: SISTEMA DE GESTION INTEGRADO
E3: REPORTE DIARIO DE ACTIVIDADES DEL TURNO | S3: REV. 0
S4: FECHA:
C6: Fecha: | K6: Promedio HH.EE Cuadrillas Mineria | M6: =+G37 -> #DIV/0!
C7: Turno: | K7: Cumplimiento Actividades | M7: =+H39 -> 0.775
C8: Jefe de Turno: | J8: Resumen | K8: Total MLB | M8: =+G57 -> 330.6
C9: Grupo: | J9: de KPI | K9: Total M3 Marina | M9: =+G71 -> 0
K10: Total M3 Shotcrete | M10: =+G81 -> 7
K11: Total Avance en Ciclo Minero | M11: =+#REF! -> #REF!
K12: Total Dotación Turno | M12: =+D15+D16+D17+D18 -> 0
B14: DOTACION
B15: Minería | C15: Trabajadores | D15: =+K15+P15 -> 0 | H15: Electricistas | J15: Trabajadores | N15: Mecánicos | O15: Trabajadores
C16: Supervisores | D16: =+K16+P16 -> 0 | J16: Supervisores | O16: Supervisores
B17: OO.CC | C17: Trabajadores | D17: =+K17+P17 -> 0 | H17: Servicios | J17: Trabajadores | N17: Subcontratos | O17: Trabajadores
C18: Supervisores | D18: =+K18+P18 -> 0 | J18: Supervisores | O18: Supervisores
B19: Frente | C19: Gal. Inyec. Sur nodo 3500
B20: NIVEL | C20: POSTURA | D20: ACTIVIDAD | E20: DISCIPLINA | F20: RECURSO (CUADRILLA) | G20: EQUIPO ASIGNADO | H20: HORA INICIO | I20: HORA TERMINO | J20: DURACIÓN ACTIVIDAD | K20: CANTIDAD REALIZADA (Pernos, Malla, Shotcrete, Baldadas, Tiros, etc) | L20: UNIDAD | M20: LARGO PERFORACIÓN (m) (Actividades Jumbos) | N20: % AVANCE DE LA ACTIVIDAD | O20: DETALLE DE LA ACTIVIDAD | P20: PERDIDAS OPERACIONALES (PO) | Q20: HORA INICIO | R20: HORA TERMINO | S20: DURACIÓN INTERFERENCIA | U20: PONDERACIÓN CICLO | V20: MLB | W20: Baldadas | X20: Shotcrete
C21: =+Datos!R2 -> Ciclo Minero 10,0 x 7,2 m Galería Inyección Principal | D21: Limpieza de Pata | E21: Minería | F21: G2-3500 | G21: Retroexcavadora 1 | H21: 0.39583333 | I21: 0.41666667 | J21: =I21-H21 -> 0.020833333 | K21: 0 | M21: 0 | N21: 0.8 | S21: =+MOD(R21-Q21,1) -> 0 | U21: =+IFERROR(VLOOKUP(D21,Datos!$R$3:$T$19,3,FALSE), "0") -> 0.0057045066 | V21: =IF(OR(D21="Perforación de Fortificación", D21="Perforación de Avance", D21="Perforación Desquinche"), K21*M21, "") | W21: =IF(D21="Extracción de Marina Disparo",K21,"") | X21: =IF(OR(D21="Shotcrete", D21="Pre Shotcrete"), K21, "")
C22: =+C21 -> Ciclo Minero 10,0 x 7,2 m Galería Inyección Principal | D22: Perforación de Avance | E22: Minería | F22: G2-3500 | G22: Jumbo 1 | H22: 0.41666667 | I22: 0.61111111 | J22: =I22-H22 -> 0.19444444 | K22: 73 | L22: Perf | M22: 3.8 | N22: 1 | S22: =+MOD(R22-Q22,1) -> 0 | U22: =+IFERROR(VLOOKUP(D22,Datos!$R$3:$T$19,3,FALSE), "0") -> 0.13519681 | V22: =IF(OR(D22="Perforación de Fortificación", D22="Perforación de Avance", D22="Perforación Desquinche"), K22*M22, "") -> 277.4 | W22: =IF(D22="Extracción de Marina Disparo",K22,"") | X22: =IF(OR(D22="Shotcrete", D22="Pre Shotcrete"), K22, "")
C23: =+C22 -> Ciclo Minero 10,0 x 7,2 m Galería Inyección Principal | D23: Limpieza de Pata | E23: Minería | F23: G2-3500 | G23: Retroexcavadora 1 | H23: 0.625 | I23: 0.64583333 | J23: =I23-H23 -> 0.020833333 | K23: 0 | M23: 0 | N23: 0.2 | S23: =+MOD(R23-Q23,1) -> 0 | U23: =+IFERROR(VLOOKUP(D23,Datos!$R$3:$T$19,3,FALSE), "0") -> 0.0057045066 | V23: =IF(OR(D23="Perforación de Fortificación", D23="Perforación de Avance", D23="Perforación Desquinche"), K23*M23, "") | W23: =IF(D23="Extracción de Marina Disparo",K23,"") | X23: =IF(OR(D23="Shotcrete", D23="Pre Shotcrete"), K23, "")
C24: =+C23 -> Ciclo Minero 10,0 x 7,2 m Galería Inyección Principal | D24: Carguío | E24: Minería | F24: G2-3500 | G24: MT1 | H24: 0.66666667 | I24: 0.6875 | J24: =I24-H24 -> 0.020833333 | K24: 73 | L24: Perf | M24: 3.8 | N24: 1 | S24: =+MOD(R24-Q24,1) -> 0 | U24: =+IFERROR(VLOOKUP(D24,Datos!$R$3:$T$19,3,FALSE), "0") -> 0 | V24: =IF(OR(D24="Perforación de Fortificación", D24="Perforación de Avance", D24="Perforación Desquinche"), K24*M24, "") | W24: =IF(D24="Extracción de Marina Disparo",K24,"") | X24: =IF(OR(D24="Shotcrete", D24="Pre Shotcrete"), K24, "")
J25: =SUM(J21:J24) -> 0.25694444 | S25: =+MOD(R25-Q25,1) -> 0 | U25: =+IFERROR(VLOOKUP(D25,Datos!$R$3:$T$19,3,FALSE), "0") -> 0 | V25: =IF(OR(D25="Perforación de Fortificación", D25="Perforación de Avance", D25="Perforación Desquinche"), K25*M25, "") | W25: =IF(D25="Extracción de Marina Disparo",K25,"") | X25: =IF(OR(D25="Shotcrete", D25="Pre Shotcrete"), K25, "")
S26: =+MOD(R26-Q26,1) -> 0 | U26: =+IFERROR(VLOOKUP(D26,Datos!$R$3:$T$19,3,FALSE), "0") -> 0 | V26: =IF(OR(D26="Perforación de Fortificación", D26="Perforación de Avance", D26="Perforación Desquinche"), K26*M26, "") | W26: =IF(D26="Extracción de Marina Disparo",K26,"") | X26: =IF(OR(D26="Shotcrete", D26="Pre Shotcrete"), K26, "")
B27: Frente | C27: Galeria Auxiliar nodo 3700
B28: NIVEL | C28: POSTURA | D28: ACTIVIDAD | E28: DISCIPLINA | F28: RECURSO (CUADRILLA) | G28: EQUIPO ASIGNADO | H28: HORA INICIO | I28: HORA TERMINO | J28: DURACIÓN ACTIVIDAD | K28: CANTIDAD REALIZADA (Pernos, Malla, Shotcrete, Baldadas, Tiros, etc) | L28: UNIDAD | M28: LARGO PERFORACIÓN (m) (Actividades Jumbos) | N28: % AVANCE DE LA ACTIVIDAD | O28: DETALLE DE LA ACTIVIDAD | P28: INTERFERENCIAS REGISTRADAS | Q28: HORA INICIO | R28: HORA TERMINO | S28: DURACIÓN INTERFERENCIA | U28: PONDERACIÓN CICLO | V28: MLB | W28: Baldadas | X28: Baldadas
C29: =+Datos!R23 -> Ciclo Minero 5,2 x 5,6 m Galería Acceso Portal de Servicio | D29: Instalación de Malla | E29: Minería | F29: G2-3700 | G29: MT2 | H29: 0.40625 | I29: 0.59722222 | J29: =I29-H29 -> 0.19097222 | K29: =14.43*3.5 -> 50.505 | L29: m² | M29: - | N29: 1 | O29: Se saca y recambia malla instalada + malla instalación ( se considera solo perimetro de avance) | S29: =+MOD(R29-Q29,1) -> 0 | U29: =+IFERROR(VLOOKUP(D29,Datos!$R$24:$T$40,3,FALSE), "0") -> 0.073313783 | V29: =IF(OR(D29="Perforación de Fortificación", D29="Perforación de Avance", D29="Perforación Desquinche"), K29*M29, "") | W29: =IF(D29="Extracción de Marina Disparo",K29,"") | X29: =IF(OR(D29="Shotcrete", D29="Pre Shotcrete"), K29, "")
C30: =+C29 -> Ciclo Minero 5,2 x 5,6 m Galería Acceso Portal de Servicio | D30: Pre Shotcrete | E30: Minería | F30: G2-3700 | G30: Roboshot 1 | H30: 0.5625 | I30: 0.60416667 | J30: =I30-H30 -> 0.041666667 | K30: 7 | L30: m³ | M30: 0 | N30: 1 | S30: =+MOD(R30-Q30,1) -> 0 | U30: =+IFERROR(VLOOKUP(D30,Datos!$R$24:$T$40,3,FALSE), "0") -> 0 | V30: =IF(OR(D30="Perforación de Fortificación", D30="Perforación de Avance", D30="Perforación Desquinche"), K30*M30, "") | W30: =IF(D30="Extracción de Marina Disparo",K30,"") | X30: =IF(OR(D30="Shotcrete", D30="Pre Shotcrete"), K30, "") -> 7
C31: =+C30 -> Ciclo Minero 5,2 x 5,6 m Galería Acceso Portal de Servicio | D31: Limpieza de Pata | E31: Minería | F31: G2-3700 | G31: Retroexcavadora 1 | H31: 0.625 | I31: 0.64583333 | J31: =I31-H31 -> 0.020833333 | N31: 1 | S31: =+MOD(R31-Q31,1) -> 0 | U31: =+IFERROR(VLOOKUP(D31,Datos!$R$24:$T$40,3,FALSE), "0") -> 0.0097751711 | V31: =IF(OR(D31="Perforación de Fortificación", D31="Perforación de Avance", D31="Perforación Desquinche"), K31*M31, "") | W31: =IF(D31="Extracción de Marina Disparo",K31,"") | X31: =IF(OR(D31="Shotcrete", D31="Pre Shotcrete"), K31, "")
C32: =+C31 -> Ciclo Minero 5,2 x 5,6 m Galería Acceso Portal de Servicio | D32: Perforación de Avance | E32: Minería | F32: G2-3700 | G32: Jumbo 1 | H32: 0.64583333 | I32: 0.66666667 | J32: =I32-H32 -> 0.020833333 | K32: =70*N32 -> 14 | L32: Tiros | M32: 3.8 | N32: 0.2 | S32: =+MOD(R32-Q32,1) -> 0 | U32: =+IFERROR(VLOOKUP(D32,Datos!$R$24:$T$40,3,FALSE), "0") -> 0.12609971 | V32: =IF(OR(D32="Perforación de Fortificación", D32="Perforación de Avance", D32="Perforación Desquinche"), K32*M32, "") -> 53.2 | W32: =IF(D32="Extracción de Marina Disparo",K32,"") | X32: =IF(OR(D32="Shotcrete", D32="Pre Shotcrete"), K32, "")
J33: =SUM(J29:J32) -> 0.27430556 | S33: =+MOD(R33-Q33,1) -> 0 | U33: =+IFERROR(VLOOKUP(D33,Datos!$R$24:$T$40,3,FALSE), "0") -> 0 | V33: =IF(OR(D33="Perforación de Fortificación", D33="Perforación de Avance", D33="Perforación Desquinche"), K33*M33, "") | W33: =IF(D33="Extracción de Marina Disparo",K33,"") | X33: =IF(OR(D33="Shotcrete", D33="Pre Shotcrete"), K33, "")
C35: KPI de Control Cuadrillas | G35: 3700 | I35: 3500
C36: Cantidad de Cuadrillas Mineras | D36: =SUMPRODUCT((LEFT(F21:F33, 1)="C") / (COUNTIF(F21:F33, F21:F33 & "") + (F21:F33=""))) -> 0 | E36: Meta Horas Efectivas | G36: 0.27083333 | H36: % Cumplimiento | I36: 0.27083333 | J36: % Cumplimiento
C37: Cantidad de Cuadrillas OO.CC | D37: =SUMPRODUCT((LEFT(F21:F33, 1)="O") / (COUNTIF(F21:F33, F21:F33 & "") + (F21:F33=""))) -> 0 | E37: Horas Efectivas Cuadrillas Mineras (Promedio) | G37: =+SUM(SUMIF($F$21:$F$33, "C*", $J$21:$J$33))/SUMPRODUCT((LEFT(F21:F33, 1)="C") / (COUNTIF(F21:F33, F21:F33 & "") + (F21:F33=""))) -> #DIV/0! | H37: =+G37*24/($G$36*24) -> #DIV/0! | I37: =+SUM(SUMIF($F$21:$F$33, "C*", $J$21:$J$33))/SUMPRODUCT((LEFT(H21:H33, 1)="C") / (COUNTIF(H21:H33, H21:H33 & "") + (H21:H33=""))) -> #DIV/0! | J37: =+I37*24/($G$36*24) -> #DIV/0!
E38: Horas Efectivas Cuadrillas OO.CC (Promedio) | G38: =+SUM(SUMIF($F$21:$F$33, "o*", $J$21:$J$33)) -> 0 | H38: =+G38*24/($G$36*24) -> 0 | I38: =+SUM(SUMIF($F$21:$F$33, "o*", $J$21:$J$33)) -> 0 | J38: =+I38*24/($G$36*24) -> 0
E39: % Cumplimiento de Actividades | H39: =+AVERAGE(N21:N33) -> 0.775 | J39: =+AVERAGE(P21:P33) -> #DIV/0!
I41: Avance Venta | K41: Valor Metro Lineal ($/m) | M41: Av. Disp. | O41: HH unitaria | P41: HH total
E42: % Av. 3700 | H42: =SUMPRODUCT(N29:N33 * U29:U33 * (N29:N33<>"") * (U29:U33<>"")) -> 0.1083089 | I42: =+H42*$K$42*$M$42 -> 2.4447484 | K42: 6.6 | M42: 3.42 | O42: 56.080976 | P42: =+O42*M42*H42 -> 20.773314
E43: % Av. 3500 | H43: =+SUMPRODUCT(N21:N25 * U21:U25 * (N21:N25<>"") * (U21:U25<>"")) -> 0.14090131 | I43: =+H43*$K$43*$M$43 -> 5.6862133 | K43: 11.8 | M43: 3.42 | O43: 118.52056 | P43: =+O43*M43*H43 -> 57.11298
P44: =SUM(P41:P43) -> 77.886294
...

Sheet 02-07B
S1: CODIGO:
E2: SISTEMA DE GESTION INTEGRADO
E3: REPORTE DIARIO DE ACTIVIDADES DEL TURNO | S3: REV. 0
S4: FECHA:
C6: Fecha: | K6: Promedio HH.EE Cuadrillas Mineria | M6: =+G37 -> #DIV/0!
C7: Turno: | K7: Cumplimiento Actividades | M7: =+H39 -> 0.9
C8: Jefe de Turno: | J8: Resumen | K8: Total MLB | M8: =+G57 -> 212.8
C9: Grupo: | J9: de KPI | K9: Total M3 Marina | M9: =+G71 -> 279.3
K10: Total M3 Shotcrete | M10: =+G81 -> 0
K11: Total Avance en Ciclo Minero | M11: =+#REF! -> #REF!
K12: Total Dotación Turno | M12: =+D15+D16+D17+D18 -> 0
B14: DOTACION
B15: Minería | C15: Trabajadores | D15: =+K15+P15 -> 0 | H15: Electricistas | J15: Trabajadores | N15: Mecánicos | O15: Trabajadores
C16: Supervisores | D16: =+K16+P16 -> 0 | J16: Supervisores | O16: Supervisores
B17: OO.CC | C17: Trabajadores | D17: =+K17+P17 -> 0 | H17: Servicios | J17: Trabajadores | N17: Subcontratos | O17: Trabajadores
C18: Supervisores | D18: =+K18+P18 -> 0 | J18: Supervisores | O18: Supervisores
B19: Frente | C19: Gal. Inyec. Sur nodo 3500
B20: NIVEL | C20: POSTURA | D20: ACTIVIDAD | E20: DISCIPLINA | F20: RECURSO (CUADRILLA) | G20: EQUIPO ASIGNADO | H20: HORA INICIO | I20: HORA TERMINO | J20: DURACIÓN ACTIVIDAD | K20: CANTIDAD REALIZADA (Pernos, Malla, Shotcrete, Baldadas, Tiros, etc) | L20: UNIDAD | M20: LARGO PERFORACIÓN (m) (Actividades Jumbos) | N20: % AVANCE DE LA ACTIVIDAD | O20: DETALLE DE LA ACTIVIDAD | P20: PERDIDAS OPERACIONALES (PO) | Q20: HORA INICIO | R20: HORA TERMINO | S20: DURACIÓN INTERFERENCIA | U20: PONDERACIÓN CICLO | V20: MLB | W20: Baldadas | X20: Shotcrete
C21: =+Datos!R2 -> Ciclo Minero 10,0 x 7,2 m Galería Inyección Principal | D21: Extracción de Marina Disparo | E21: Minería | F21: G2-3500 | G21: Scoop 1 | H21: 0.95833333 | I21: 0.20833333 | J21: 0.27083333 | K21: 57 | L21: Baldadas | M21: 0 | N21: 1 | S21: =+MOD(R21-Q21,1) -> 0 | U21: =+IFERROR(VLOOKUP(D21,Datos!$R$3:$T$19,3,FALSE), "0") -> 0.22475756 | V21: =IF(OR(D21="Perforación de Fortificación", D21="Perforación de Avance", D21="Perforación Desquinche"), K21*M21, "") | W21: =IF(D21="Extracción de Marina Disparo",K21,"") -> 57 | X21: =IF(OR(D21="Shotcrete", D21="Pre Shotcrete"), K21, "")
C22: =+C21 -> Ciclo Minero 10,0 x 7,2 m Galería Inyección Principal | D22: Acuñadura Mecanizada | E22: Minería | F22: G2-3500 | G22: Acuñador 1 | H22: 0.22916667 | I22: 0.27083333 | J22: =I22-H22 -> 0.041666667 | K22: 50 | L22: m² | M22: 50 | N22: 0.8 | S22: =+MOD(R22-Q22,1) -> 0 | U22: =+IFERROR(VLOOKUP(D22,Datos!$R$3:$T$19,3,FALSE), "0") -> 0.042783799 | V22: =IF(OR(D22="Perforación de Fortificación", D22="Perforación de Avance", D22="Perforación Desquinche"), K22*M22, "") | W22: =IF(D22="Extracción de Marina Disparo",K22,"") | X22: =IF(OR(D22="Shotcrete", D22="Pre Shotcrete"), K22, "")
J23: =SUM(J19:J22) -> 0.3125 | U23: =+IFERROR(VLOOKUP(D23,Datos!$R$3:$T$19,3,FALSE), "0") -> 0 | V23: =IF(OR(D23="Perforación de Fortificación", D23="Perforación de Avance", D23="Perforación Desquinche"), K23*M23, "") | W23: =IF(D23="Extracción de Marina Disparo",K23,"") | X23: =IF(OR(D23="Shotcrete", D23="Pre Shotcrete"), K23, "")
U24: =+IFERROR(VLOOKUP(D24,Datos!$R$3:$T$19,3,FALSE), "0") -> 0 | V24: =IF(OR(D24="Perforación de Fortificación", D24="Perforación de Avance", D24="Perforación Desquinche"), K24*M24, "") | W24: =IF(D24="Extracción de Marina Disparo",K24,"") | X24: =IF(OR(D24="Shotcrete", D24="Pre Shotcrete"), K24, "")
S25: =+MOD(R25-Q25,1) -> 0 | U25: =+IFERROR(VLOOKUP(D25,Datos!$R$3:$T$19,3,FALSE), "0") -> 0 | V25: =IF(OR(D25="Perforación de Fortificación", D25="Perforación de Avance", D25="Perforación Desquinche"), K25*M25, "") | W25: =IF(D25="Extracción de Marina Disparo",K25,"") | X25: =IF(OR(D25="Shotcrete", D25="Pre Shotcrete"), K25, "")
S26: =+MOD(R26-Q26,1) -> 0 | U26: =+IFERROR(VLOOKUP(D26,Datos!$R$3:$T$19,3,FALSE), "0") -> 0 | V26: =IF(OR(D26="Perforación de Fortificación", D26="Perforación de Avance", D26="Perforación Desquinche"), K26*M26, "") | W26: =IF(D26="Extracción de Marina Disparo",K26,"") | X26: =IF(OR(D26="Shotcrete", D26="Pre Shotcrete"), K26, "")
B27: Frente | C27: Galeria Auxiliar nodo 3700
B28: NIVEL | C28: POSTURA | D28: ACTIVIDAD | E28: DISCIPLINA | F28: RECURSO (CUADRILLA) | G28: EQUIPO ASIGNADO | H28: HORA INICIO | I28: HORA TERMINO | J28: DURACIÓN ACTIVIDAD | K28: CANTIDAD REALIZADA (Pernos, Malla, Shotcrete, Baldadas, Tiros, etc) | L28: UNIDAD | M28: LARGO PERFORACIÓN (m) (Actividades Jumbos) | N28: % AVANCE DE LA ACTIVIDAD | O28: DETALLE DE LA ACTIVIDAD | P28: INTERFERENCIAS REGISTRADAS | Q28: HORA INICIO | R28: HORA TERMINO | S28: DURACIÓN INTERFERENCIA | U28: PONDERACIÓN CICLO | V28: MLB | W28: Baldadas | X28: Baldadas
C29: =+Datos!R23 -> Ciclo Minero 5,2 x 5,6 m Galería Acceso Portal de Servicio | D29: Perforación de Avance | E29: Minería | F29: G2-3700 | G29: Jumbo 1 | H29: 0.9375 | I29: 0.11458333 | J29: 0.17708333 | K29: =70*N29 -> 56 | L29: Perf | M29: 3.8 | N29: 0.8 | S29: =+MOD(R29-Q29,1) -> 0 | U29: =+IFERROR(VLOOKUP(D29,Datos!$R$24:$T$40,3,FALSE), "0") -> 0.12609971 | V29: =IF(OR(D29="Perforación de Fortificación", D29="Perforación de Avance", D29="Perforación Desquinche"), K29*M29, "") -> 212.8 | W29: =IF(D29="Extracción de Marina Disparo",K29,"") | X29: =IF(OR(D29="Shotcrete", D29="Pre Shotcrete"), K29, "")
C30: =+C29 -> Ciclo Minero 5,2 x 5,6 m Galería Acceso Portal de Servicio | D30: Carguío | E30: Minería | F30: G2-3700 | G30: MT2 | H30: 0.125 | I30: 0.27083333 | J30: =I30-H30 -> 0.14583333 | K30: 70 | L30: Perf | M30: 0 | N30: 1 | S30: =+MOD(R30-Q30,1) -> 0 | U30: =+IFERROR(VLOOKUP(D30,Datos!$R$24:$T$40,3,FALSE), "0") -> 0 | V30: =IF(OR(D30="Perforación de Fortificación", D30="Perforación de Avance", D30="Perforación Desquinche"), K30*M30, "") | W30: =IF(D30="Extracción de Marina Disparo",K30,"") | X30: =IF(OR(D30="Shotcrete", D30="Pre Shotcrete"), K30, "")
J31: =I31-H31 -> 0 | S31: =+MOD(R31-Q31,1) -> 0 | U31: =+IFERROR(VLOOKUP(D31,Datos!$R$24:$T$40,3,FALSE), "0") -> 0 | V31: =IF(OR(D31="Perforación de Fortificación", D31="Perforación de Avance", D31="Perforación Desquinche"), K31*M31, "") | W31: =IF(D31="Extracción de Marina Disparo",K31,"") | X31: =IF(OR(D31="Shotcrete", D31="Pre Shotcrete"), K31, "")
J32: =I32-H32 -> 0 | S32: =+MOD(R32-Q32,1) -> 0 | U32: =+IFERROR(VLOOKUP(D32,Datos!$R$24:$T$40,3,FALSE), "0") -> 0 | V32: =IF(OR(D32="Perforación de Fortificación", D32="Perforación de Avance", D32="Perforación Desquinche"), K32*M32, "") | W32: =IF(D32="Extracción de Marina Disparo",K32,"") | X32: =IF(OR(D32="Shotcrete", D32="Pre Shotcrete"), K32, "")
J33: =SUM(J29:J32) -> 0.32291667 | S33: =+MOD(R33-Q33,1) -> 0 | U33: =+IFERROR(VLOOKUP(D33,Datos!$R$24:$T$40,3,FALSE), "0") -> 0 | V33: =IF(OR(D33="Perforación de Fortificación", D33="Perforación de Avance", D33="Perforación Desquinche"), K33*M33, "") | W33: =IF(D33="Extracción de Marina Disparo",K33,"") | X33: =IF(OR(D33="Shotcrete", D33="Pre Shotcrete"), K33, "")
C35: KPI de Control Cuadrillas | G35: 3700 | I35: 3500
C36: Cantidad de Cuadrillas Mineras | D36: =SUMPRODUCT((LEFT(F21:F33, 1)="C") / (COUNTIF(F21:F33, F21:F33 & "") + (F21:F33=""))) -> 0 | E36: Meta Horas Efectivas | G36: 0.27083333 | H36: % Cumplimiento | I36: 0.27083333 | J36: % Cumplimiento
C37: Cantidad de Cuadrillas OO.CC | D37: =SUMPRODUCT((LEFT(F21:F33, 1)="O") / (COUNTIF(F21:F33, F21:F33 & "") + (F21:F33=""))) -> 0 | E37: Horas Efectivas Cuadrillas Mineras (Promedio) | G37: =+SUM(SUMIF($F$21:$F$33, "C*", $J$21:$J$33))/SUMPRODUCT((LEFT(F21:F33, 1)="C") / (COUNTIF(F21:F33, F21:F33 & "") + (F21:F33=""))) -> #DIV/0! | H37: =+G37*24/($G$36*24) -> #DIV/0! | I37: =+SUM(SUMIF($F$21:$F$33, "C*", $J$21:$J$33))/SUMPRODUCT((LEFT(H21:H33, 1)="C") / (COUNTIF(H21:H33, H21:H33 & "") + (H21:H33=""))) -> #DIV/0! | J37: =+I37*24/($G$36*24) -> #DIV/0!
E38: Horas Efectivas Cuadrillas OO.CC (Promedio) | G38: =+SUM(SUMIF($F$21:$F$33, "o*", $J$21:$J$33)) -> 0 | H38: =+G38*24/($G$36*24) -> 0 | I38: =+SUM(SUMIF($F$21:$F$33, "o*", $J$21:$J$33)) -> 0 | J38: =+I38*24/($G$36*24) -> 0
E39: % Cumplimiento de Actividades | H39: =+AVERAGE(N21:N33) -> 0.9 | J39: =+AVERAGE(P21:P33) -> #DIV/0!
I41: Avance Venta | K41: Valor Metro Lineal ($/m) | M41: Av. Disp. | O41: HH unitaria | P41: HH total
E42: % Av. 3700 | H42: =SUMPRODUCT(N29:N33 * U29:U33 * (N29:N33<>"") * (U29:U33<>"")) -> 0.10087977 | I42: =+H42*$K$42*$M$42 -> 2.2770581 | K42: 6.6 | M42: 3.42 | O42: 56.080976 | P42: =+O42*M42*H42 -> 19.34843
E43: % Av. 3500 | H43: =+SUMPRODUCT(N21:N25 * U21:U25 * (N21:N25<>"") * (U21:U25<>"")) -> 0.2589846 | I43: =+H43*$K$43*$M$43 -> 10.451582 | K43: 11.8 | M43: 3.42 | O43: 118.52056 | P43: =+O43*M43*H43 -> 104.97689
P44: =SUM(P41:P43) -> 124.32532
...

Sheet 03-07A
S1: CODIGO:
E2: SISTEMA DE GESTION INTEGRADO
E3: REPORTE DIARIO DE ACTIVIDADES DEL TURNO | S3: REV. 0
S4: FECHA:
C6: Fecha: | K6: Promedio HH.EE Cuadrillas Mineria | M6: =+G38 -> 0.64583333
C7: Turno: | K7: Cumplimiento Actividades | M7: =+H39 -> 1
C8: Jefe de Turno: | J8: Resumen | K8: Total MLB | M8: =+G59 -> 0
C9: Grupo: | J9: de KPI | K9: Total M3 Marina | M9: =+G73 -> 0
K10: Total M3 Shotcrete | M10: =+G83 -> 0
K11: Total Avance en Ciclo Minero | M11: =+#REF! -> #REF!
K12: Total Dotación Turno | M12: =+D15+D16+D17+D18 -> 0
B14: DOTACION
B15: Minería | C15: Trabajadores | D15: =+K15+P15 -> 0 | H15: Electricistas | J15: Trabajadores | N15: Mecánicos | O15: Trabajadores
C16: Supervisores | D16: =+K16+P16 -> 0 | J16: Supervisores | O16: Supervisores
B17: OO.CC | C17: Trabajadores | D17: =+K17+P17 -> 0 | H17: Servicios | J17: Trabajadores | N17: Subcontratos | O17: Trabajadores
C18: Supervisores | D18: =+K18+P18 -> 0 | J18: Supervisores | O18: Supervisores
B19: Frente | C19: Gal. Inyec. Sur nodo 3500
B20: NIVEL | C20: POSTURA | D20: ACTIVIDAD | E20: DISCIPLINA | F20: RECURSO (CUADRILLA) | G20: EQUIPO ASIGNADO | H20: HORA INICIO | I20: HORA TERMINO | J20: DURACIÓN ACTIVIDAD | K20: CANTIDAD REALIZADA (Pernos, Malla, Shotcrete, Baldadas, Tiros, etc) | L20: UNIDAD | M20: LARGO PERFORACIÓN (m) (Actividades Jumbos) | N20: % AVANCE DE LA ACTIVIDAD | O20: DETALLE DE LA ACTIVIDAD | P20: PERDIDAS OPERACIONALES (PO) | Q20: HORA INICIO | R20: HORA TERMINO | S20: DURACIÓN INTERFERENCIA | U20: PONDERACIÓN CICLO | V20: MLB | W20: Baldadas | X20: Shotcrete
C21: =+Datos!R2 -> Ciclo Minero 10,0 x 7,2 m Galería Inyección Principal | D21: Acuñadura Mecanizada | E21: Minería | F21: G2-3500 | G21: MT G-55 | H21: 0.41666667 | I21: 0.45833333 | J21: =MOD(I21-H21, 1) -> 0.041666667 | K21: 1 | M21: - | N21: 1 | S21: =+MOD(R21-Q21,1) -> 0 | U21: =+IFERROR(VLOOKUP(D21,Datos!$R$3:$T$19,3,FALSE), "0") -> 0.042783799 | V21: =IF(OR(D21="Perforación de Fortificación", D21="Perforación de Avance", D21="Perforación Desquinche"), K21*M21, "") | W21: =IF(D21="Extracción de Marina Disparo",K21,"") | X21: =IF(OR(D21="Shotcrete", D21="Pre Shotcrete"), K21, "")
C22: =+C21 -> Ciclo Minero 10,0 x 7,2 m Galería Inyección Principal | D22: Limpieza de Pata | E22: Minería | F22: G2-3500 | G22: Retroexcavadora RT-14 | H22: 0.45833333 | I22: 0.5 | J22: =MOD(I22-H22, 1) -> 0.041666667 | K22: 3 | L22: Baldadas | M22: 0 | N22: 1 | S22: =+MOD(R22-Q22,1) -> 0 | U22: =+IFERROR(VLOOKUP(D22,Datos!$R$3:$T$19,3,FALSE), "0") -> 0.0057045066 | V22: =IF(OR(D22="Perforación de Fortificación", D22="Perforación de Avance", D22="Perforación Desquinche"), K22*M22, "") | W22: =IF(D22="Extracción de Marina Disparo",K22,"") | X22: =IF(OR(D22="Shotcrete", D22="Pre Shotcrete"), K22, "")
C23: =+C22 -> Ciclo Minero 10,0 x 7,2 m Galería Inyección Principal | D23: Topografía | E23: Minería | F23: G2-3500 | H23: 0.5 | I23: 0.53125 | J23: =MOD(I23-H23, 1) -> 0.03125 | N23: 1 | S23: =+MOD(R23-Q23,1) -> 0 | U23: =+IFERROR(VLOOKUP(D23,Datos!$R$3:$T$19,3,FALSE), "0") -> 0.034227039 | V23: =IF(OR(D23="Perforación de Fortificación", D23="Perforación de Avance", D23="Perforación Desquinche"), K23*M23, "") | W23: =IF(D23="Extracción de Marina Disparo",K23,"") | X23: =IF(OR(D23="Shotcrete", D23="Pre Shotcrete"), K23, "")
C24: =+C23 -> Ciclo Minero 10,0 x 7,2 m Galería Inyección Principal | D24: Perforación de Fortificación | E24: Minería | F24: G2-3500 | G24: Jumbo J-24 | H24: 0.54166667 | I24: 0.625 | J24: =MOD(I24-H24, 1) -> 0.083333333 | K24: 40 | L24: Perf | M24: 4 | N24: 1 | S24: =+MOD(R24-Q24,1) -> 0 | U24: =+IFERROR(VLOOKUP(D24,Datos!$R$3:$T$19,3,FALSE), "0") -> 0.086138049 | V24: =IF(OR(D24="Perforación de Fortificación", D24="Perforación de Avance", D24="Perforación Desquinche"), K24*M24, "") -> 160 | W24: =IF(D24="Extracción de Marina Disparo",K24,"") | X24: =IF(OR(D24="Shotcrete", D24="Pre Shotcrete"), K24, "")
C25: =+C24 -> Ciclo Minero 10,0 x 7,2 m Galería Inyección Principal | D25: Lechado de Pernos | E25: Minería | F25: G2-3500 | G25: MT G-55 | H25: 0.64583333 | I25: 0.77083333 | J25: =MOD(I25-H25, 1) -> 0.125 | K25: 40 | L25: Pernos | N25: 1 | S25: =+MOD(R25-Q25,1) -> 0 | U25: =+IFERROR(VLOOKUP(D25,Datos!$R$3:$T$19,3,FALSE), "0") -> 0.1779806 | V25: =IF(OR(D25="Perforación de Fortificación", D25="Perforación de Avance", D25="Perforación Desquinche"), K25*M25, "") | W25: =IF(D25="Extracción de Marina Disparo",K25,"") | X25: =IF(OR(D25="Shotcrete", D25="Pre Shotcrete"), K25, "")
J26: =SUM(J21:J25) -> 0.32291667 | O26: Ajuste de ciclo para a la actividad | S26: =+MOD(R26-Q26,1) -> 0 | U26: =SUM(Datos!T4:T13)-SUM(U21:U25) -> 0.0867085 | V26: =IF(OR(D26="Perforación de Fortificación", D26="Perforación de Avance", D26="Perforación Desquinche"), K26*M26, "") | W26: =IF(D26="Extracción de Marina Disparo",K26,"") | X26: =IF(OR(D26="Shotcrete", D26="Pre Shotcrete"), K26, "")
B27: Frente | C27: Galeria Auxiliar nodo 3700
B28: NIVEL | C28: POSTURA | D28: ACTIVIDAD | E28: DISCIPLINA | F28: RECURSO (CUADRILLA) | G28: EQUIPO ASIGNADO | H28: HORA INICIO | I28: HORA TERMINO | J28: DURACIÓN ACTIVIDAD | K28: CANTIDAD REALIZADA (Pernos, Malla, Shotcrete, Baldadas, Tiros, etc) | L28: UNIDAD | M28: LARGO PERFORACIÓN (m) (Actividades Jumbos) | N28: % AVANCE DE LA ACTIVIDAD | O28: DETALLE DE LA ACTIVIDAD | P28: INTERFERENCIAS REGISTRADAS | Q28: HORA INICIO | R28: HORA TERMINO | S28: DURACIÓN INTERFERENCIA | U28: PONDERACIÓN CICLO | V28: MLB | W28: Baldadas | X28: Baldadas
C29: =+Datos!R23 -> Ciclo Minero 5,2 x 5,6 m Galería Acceso Portal de Servicio | D29: Limpieza de Pata | E29: Minería | F29: G2-3700 | G29: Retroexcavadora RT-14 | H29: 0.45833333 | I29: 0.5 | J29: =MOD(I29-H29, 1) -> 0.041666667 | K29: 3 | L29: Baldadas | M29: 0 | N29: 1 | S29: =+MOD(R29-Q29,1) -> 0 | U29: =+IFERROR(VLOOKUP(D29,Datos!$R$24:$T$40,3,FALSE), "0") -> 0.0097751711 | V29: =IF(OR(D29="Perforación de Fortificación", D29="Perforación de Avance", D29="Perforación Desquinche"), K29*M29, "") | W29: =IF(D29="Extracción de Marina Disparo",K29,"") | X29: =IF(OR(D29="Shotcrete", D29="Pre Shotcrete"), K29, "")
C30: =+C29 -> Ciclo Minero 5,2 x 5,6 m Galería Acceso Portal de Servicio | D30: Extracción de Marina Disparo | E30: Minería | F30: G2-3700 | G30: Scoop ST1030 S-33 | H30: 0.58333333 | I30: 0.70833333 | J30: =MOD(I30-H30, 1) -> 0.125 | K30: 45 | L30: Baldadas | M30: 0 | N30: 1 | S30: =+MOD(R30-Q30,1) -> 0 | U30: =+IFERROR(VLOOKUP(D30,Datos!$R$24:$T$40,3,FALSE), "0") -> 0.17399804 | V30: =IF(OR(D30="Perforación de Fortificación", D30="Perforación de Avance", D30="Perforación Desquinche"), K30*M30, "") | W30: =IF(D30="Extracción de Marina Disparo",K30,"") -> 45 | X30: =IF(OR(D30="Shotcrete", D30="Pre Shotcrete"), K30, "")
C31: =+C30 -> Ciclo Minero 5,2 x 5,6 m Galería Acceso Portal de Servicio | D31: Extracción de Marina Superficie | E31: Minería | F31: G2-3700 | H31: 0.70833333 | I31: 0.75 | J31: =MOD(I31-H31, 1) -> 0.041666667 | K31: 9 | L31: Viajes | S31: =+MOD(R31-Q31,1) -> 0 | U31: =+IFERROR(VLOOKUP(D31,Datos!$R$24:$T$40,3,FALSE), "0") -> 0 | V31: =IF(OR(D31="Perforación de Fortificación", D31="Perforación de Avance", D31="Perforación Desquinche"), K31*M31, "") | W31: =IF(D31="Extracción de Marina Disparo",K31,"") | X31: =IF(OR(D31="Shotcrete", D31="Pre Shotcrete"), K31, "")
C32: =+C31 -> Ciclo Minero 5,2 x 5,6 m Galería Acceso Portal de Servicio | J32: =MOD(I32-H32, 1) -> 0 | S32: =+MOD(R32-Q32,1) -> 0 | U32: =+IFERROR(VLOOKUP(D32,Datos!$R$24:$T$40,3,FALSE), "0") -> 0 | V32: =IF(OR(D32="Perforación de Fortificación", D32="Perforación de Avance", D32="Perforación Desquinche"), K32*M32, "") | W32: =IF(D32="Extracción de Marina Disparo",K32,"") | X32: =IF(OR(D32="Shotcrete", D32="Pre Shotcrete"), K32, "")
C33: =+C32 -> Ciclo Minero 5,2 x 5,6 m Galería Acceso Portal de Servicio | J33: =MOD(I33-H33, 1) -> 0 | S33: =+MOD(R33-Q33,1) -> 0 | U33: =+IFERROR(VLOOKUP(D33,Datos!$R$24:$T$40,3,FALSE), "0") -> 0 | V33: =IF(OR(D33="Perforación de Fortificación", D33="Perforación de Avance", D33="Perforación Desquinche"), K33*M33, "") | W33: =IF(D33="Extracción de Marina Disparo",K33,"") | X33: =IF(OR(D33="Shotcrete", D33="Pre Shotcrete"), K33, "")
C34: =+C33 -> Ciclo Minero 5,2 x 5,6 m Galería Acceso Portal de Servicio | J34: =SUM(J29:J33) -> 0.20833333 | S34: =+MOD(R34-Q34,1) -> 0 | V34: =IF(OR(D34="Perforación de Fortificación", D34="Perforación de Avance", D34="Perforación Desquinche"), K34*M34, "") | W34: =IF(D34="Extracción de Marina Disparo",K34,"") | X34: =IF(OR(D34="Shotcrete", D34="Pre Shotcrete"), K34, "")
C36: KPI de Control Cuadrillas | G36: 3500 | I36: 3700 | K36: Total
C37: Cantidad de Cuadrillas Mineras | D37: =SUMPRODUCT((LEFT(F21:F33, 1)="C") / (COUNTIF(F21:F33, F21:F33 & "") + (F21:F33=""))) -> 0 | E37: Meta Horas Efectivas | G37: 0.26041667 | H37: % Cumplimiento | I37: 0.26041667 | J37: % Cumplimiento | K37: =+G37 -> 0.26041667 | L37: % Cumplimiento
C38: Cantidad de Cuadrillas OO.CC | D38: =SUMPRODUCT((LEFT(F21:F33, 1)="O") / (COUNTIF(F21:F33, F21:F33 & "") + (F21:F33=""))) -> 0 | E38: Horas Efectivas | G38: =SUM(J21:J26) -> 0.64583333 | H38: =+G38*24/($G$37*24) -> 2.48 | I38: =SUM(J29:J33) -> 0.20833333 | J38: =+I38*24/($I$37*24) -> 0.8 | K38: =AVERAGE(G38+I38)/2 -> 0.42708333 | L38: =+K38*24/($K$37*24) -> 1.64
E39: % Cumplimiento de Actividades | H39: =+AVERAGE(N21:N26) -> 1 | J39: =+AVERAGE(N29:N33) -> 1 | L39: =+AVERAGE(N21:N33) -> 1
H41: % AVANCE DE LA ACTIVIDAD | I41: AVANCE VENTA | J41: VALOR METRO LENEAL ($/m) | K41: AV. DISP (m) | L41: HH unitaria | M41: HH total
E42: % Av. 3700 | H42: =SUMPRODUCT(N29:N33 * U29:U33 * (N29:N33<>"") * (U29:U33<>"")) -> 0.18377322 | I42: =+H42*$J$42*$K$42 -> 4.148129 | J42: 6.6 | K42: 3.42 | L42: 56.080976 | M42: =+L42*K42*H42 -> 35.24714
E43: % Av. 3500 | H43: =+SUMPRODUCT(N21:N26 * U21:U26 * (N21:N26<>"") * (U21:U26<>"")) -> 0.346834 | I43: =+H43*$J$43*$K$43 -> 13.996833 | J43: 11.8 | K43: 3.42 | L43: 118.52056 | M43: =+L43*K43*H43 -> 140.5858
E44: Viajes Mx Ton- km / viaje 3700 | I44: =+J44*K44 -> 3.0568666 | J44: =1892/1000000 -> 0.001892 | K44: =+((15*4.4)*2.72)*K31 -> 1615.68 | L44: 0.016919982 | M44: =+L44*K44 -> 27.337277
...

Sheet 03-07B
S1: CODIGO:
E2: SISTEMA DE GESTION INTEGRADO
E3: REPORTE DIARIO DE ACTIVIDADES DEL TURNO | S3: REV. 0
S4: FECHA:
C6: Fecha: | K6: Promedio HH.EE Cuadrillas Mineria | M6: =+G38 -> 0.65277778
C7: Turno: | K7: Cumplimiento Actividades | M7: =+H39 -> 1
C8: Jefe de Turno: | J8: Resumen | K8: Total MLB | M8: =+G59 -> 0
C9: Grupo: | J9: de KPI | K9: Total M3 Marina | M9: =+G73 -> 0
K10: Total M3 Shotcrete | M10: =+G83 -> 0
K11: Total Avance en Ciclo Minero | M11: =+#REF! -> #REF!
K12: Total Dotación Turno | M12: =+D15+D16+D17+D18 -> 0
B14: DOTACION
B15: Minería | C15: Trabajadores | D15: =+K15+P15 -> 0 | H15: Electricistas | J15: Trabajadores | N15: Mecánicos | O15: Trabajadores
C16: Supervisores | D16: =+K16+P16 -> 0 | J16: Supervisores | O16: Supervisores
B17: OO.CC | C17: Trabajadores | D17: =+K17+P17 -> 0 | H17: Servicios | J17: Trabajadores | N17: Subcontratos | O17: Trabajadores
C18: Supervisores | D18: =+K18+P18 -> 0 | J18: Supervisores | O18: Supervisores
B19: Frente | C19: Gal. Inyec. Sur nodo 3500
B20: NIVEL | C20: POSTURA | D20: ACTIVIDAD | E20: DISCIPLINA | F20: RECURSO (CUADRILLA) | G20: EQUIPO ASIGNADO | H20: HORA INICIO | I20: HORA TERMINO | J20: DURACIÓN ACTIVIDAD | K20: CANTIDAD REALIZADA (Pernos, Malla, Shotcrete, Baldadas, Tiros, etc) | L20: UNIDAD | M20: LARGO PERFORACIÓN (m) (Actividades Jumbos) | N20: % AVANCE DE LA ACTIVIDAD | O20: DETALLE DE LA ACTIVIDAD | P20: PERDIDAS OPERACIONALES (PO) | Q20: HORA INICIO | R20: HORA TERMINO | S20: DURACIÓN INTERFERENCIA | U20: PONDERACIÓN CICLO | V20: MLB | W20: Baldadas | X20: Shotcrete
C21: =+Datos!R2 -> Ciclo Minero 10,0 x 7,2 m Galería Inyección Principal | D21: Topografía | E21: Minería | F21: G2-3500 | H21: 0.875 | I21: 0.91666667 | J21: =MOD(I21-H21, 1) -> 0.041666667 | M21: - | N21: 1 | S21: =+MOD(R21-Q21,1) -> 0 | U21: =+IFERROR(VLOOKUP(D21,Datos!$R$3:$T$19,3,FALSE), "0") -> 0.034227039 | V21: =IF(OR(D21="Perforación de Fortificación", D21="Perforación de Avance", D21="Perforación Desquinche"), K21*M21, "") | W21: =IF(D21="Extracción de Marina Disparo",K21,"") | X21: =IF(OR(D21="Shotcrete", D21="Pre Shotcrete"), K21, "")
